Workbook

Sheet SAISIE
A1: BORDEREAU DES VENTES | E1: Comptabilisé :
A2: NOM | B2: SCI PAPRISO
A3: CODE JOURNAL | C3: =IF(B3="","VOUS DEVEZ SAISIR LE JOURNAL","") -> VOUS DEVEZ SAISIR LE JOURNAL
A4: MOIS | B4: 09 | C4: =IF(B4="","VOUS DEVEZ SAISIR LE MOIS","")
A5: ANNEE | B5: 2024 | C5: =IF(B5="","VOUS DEVEZ SAISIR L'ANNEE","") | J5: Code TVA facultatif
A6: FOLIO | C6: RADICAL CENTRALISATEUR | F6: =IF(E6="","VOUS DEVEZ SAISIR LE RADICAL","") -> VOUS DEVEZ SAISIR LE RADICAL | G6: =IF(G9="Libellé Cpte 1","Vous pouvez saisir le libellé du compte en dessous du numéro pour vous aider dans la saisie (aucune conséquence dans le traitement des écritures)","") -> Vous pouvez saisir le libellé du compte en dessous du numéro pour vous aider dans la saisie (aucune conséquence dans le traitement des écritures)
G7: Cpte 1 | H7: Cpte 2 | I7: Cpte 3 | J7: Cpte TVA 1 | K7: Cpte TVA 2 | L7: Cpte TVA 3 | M7: Cpte TVA 4
B8: Jour | C8: Compte | D8: Montant facture | E8: N° pièce | F8: Libellé (écriture) | N8: Libellé 2 (mouvement) | O8: Numéro Compte divers | P8: Montant divers | Q8: Quantité | S8: CONTRÔLES
G9: Libellé Cpte 1 | H9: Libellé Cpte 2 | I9: Libellé Cpte 3 | S9: =IF(J9="","",J9) | T9: =IF(K9="","",K9) | U9: =IF(L9="","",L9) | V9: =IF(M9="","",M9) | W9: Ecriture déséquilibrée | X9: Montant sans compte | Y9: Jour absent
B10: 26/08/2024 | D10: 10278 | F10: GADERO : Loyer de septembre facture n° 09-24 réglé le 27/09/2024 par virement | G10: 8565 | J10: 1713 | S10: =IF(J10="","",J10/(P10+G10+H10+I10+#REF!+#REF!+#REF!+#REF!+#REF!+#REF!+#REF!)) -> #REF! | T10: =IF(K10="","",K10/(P10+G10+H10+I10+#REF!+#REF!+#REF!+#REF!+#REF!+#REF!+#REF!)) | U10: =IF(L10="","",L10/(P10+G10+H10+I10+#REF!+#REF!+#REF!+#REF!+#REF!+#REF!+#REF!)) | V10: =IF(M10="","",M10/(P10+G10+H10+I10+#REF!+#REF!+#REF!+#REF!+#REF!+#REF!+#REF!)) | W10: =IF(SUM(P10+G10+H10+I10+#REF!+#REF!+#REF!+#REF!+#REF!+#REF!+#REF!+J10+K10+L10+M10)=D10,"",FALSE) -> #REF! | X10: =IF(OR(AND(C10="",D10<>""),AND(O10="",P10<>""),AND($G$8="",G10<>""),AND($H$8="",H10<>""),AND($I$8="",I10<>""),AND(#REF!="",#REF!<>""),AND(#REF!="",#REF!<>""),AND(#REF!="",#REF!<>""),AND(#REF!="",#REF!<>""),AND(#REF!="",#REF!<>""),AND(#REF!="",#REF!<>""),AND(#REF!="",#REF!<>""),AND($J$8="",J10<>""),AND($K$8="",K10<>""),AND($L$8="",L10<>""),AND($M$8="",M10<>"")),FALSE,"") -> #REF! | Y10: =IF(AND(B10="",OR(C10<>"",D10<>"",E10<>"",F10<>"",N10<>"",O10<>"",P10<>"",G10<>"",H10<>"",I10<>"",#REF!<>"",#REF!<>"",#REF!<>"",#REF!<>"",#REF!<>"",#REF!<>"",#REF!<>"",J10<>"",K10<>"",L10<>"",M10<>"")),FALSE,"") -> #REF!
S11: =IF(J11="","",J11/SUM(G11:I11)) | T11: =IF(K11="","",K11/SUM(G11:I11)) | U11: =IF(L11="","",L11/SUM(G11:I11)) | V11: =IF(M11="","",M11/(P11+G11+H11+I11+#REF!+#REF!+#REF!+#REF!+#REF!+#REF!+#REF!)) | W11: =IF(SUM(P11+G11+H11+I11+#REF!+#REF!+#REF!+#REF!+#REF!+#REF!+#REF!+J11+K11+L11+M11)=D11,"",FALSE) -> #REF! | X11: =IF(OR(AND(C11="",D11<>""),AND(O11="",P11<>""),AND($G$8="",G11<>""),AND($H$8="",H11<>""),AND($I$8="",I11<>""),AND(#REF!="",#REF!<>""),AND(#REF!="",#REF!<>""),AND(#REF!="",#REF!<>""),AND(#REF!="",#REF!<>""),AND(#REF!="",#REF!<>""),AND(#REF!="",#REF!<>""),AND(#REF!="",#REF!<>""),AND($J$8="",J11<>""),AND($K$8="",K11<>""),AND($L$8="",L11<>""),AND($M$8="",M11<>"")),FALSE,"") -> #REF! | Y11: =IF(AND(B11="",OR(C11<>"",D11<>"",E11<>"",F11<>"",N11<>"",O11<>"",P11<>"",G11<>"",H11<>"",I11<>"",#REF!<>"",#REF!<>"",#REF!<>"",#REF!<>"",#REF!<>"",#REF!<>"",#REF!<>"",J11<>"",K11<>"",L11<>"",M11<>"")),FALSE,"") -> #REF!
S12: =IF(J12="","",J12/SUM(G12:I12)) | T12: =IF(K12="","",K12/SUM(G12:I12)) | U12: =IF(L12="","",L12/SUM(G12:I12)) | V12: =IF(M12="","",M12/(P12+G12+H12+I12+#REF!+#REF!+#REF!+#REF!+#REF!+#REF!+#REF!)) | W12: =IF(SUM(P12+G12+H12+I12+#REF!+#REF!+#REF!+#REF!+#REF!+#REF!+#REF!+J12+K12+L12+M12)=D12,"",FALSE) -> #REF! | X12: =IF(OR(AND(C12="",D12<>""),AND(O12="",P12<>""),AND($G$8="",G12<>""),AND($H$8="",H12<>""),AND($I$8="",I12<>""),AND(#REF!="",#REF!<>""),AND(#REF!="",#REF!<>""),AND(#REF!="",#REF!<>""),AND(#REF!="",#REF!<>""),AND(#REF!="",#REF!<>""),AND(#REF!="",#REF!<>""),AND(#REF!="",#REF!<>""),AND($J$8="",J12<>""),AND($K$8="",K12<>""),AND($L$8="",L12<>""),AND($M$8="",M12<>"")),FALSE,"") -> #REF! | Y12: =IF(AND(B12="",OR(C12<>"",D12<>"",E12<>"",F12<>"",N12<>"",O12<>"",P12<>"",G12<>"",H12<>"",I12<>"",#REF!<>"",#REF!<>"",#REF!<>"",#REF!<>"",#REF!<>"",#REF!<>"",#REF!<>"",J12<>"",K12<>"",L12<>"",M12<>"")),FALSE,"") -> #REF!
S13: =IF(J13="","",J13/SUM(G13:I13)) | T13: =IF(K13="","",K13/SUM(G13:I13)) | U13: =IF(L13="","",L13/SUM(G13:I13)) | V13: =IF(M13="","",M13/(P13+G13+H13+I13+#REF!+#REF!+#REF!+#REF!+#REF!+#REF!+#REF!)) | W13: =IF(SUM(P13+G13+H13+I13+#REF!+#REF!+#REF!+#REF!+#REF!+#REF!+#REF!+J13+K13+L13+M13)=D13,"",FALSE) -> #REF! | X13: =IF(OR(AND(C13="",D13<>""),AND(O13="",P13<>""),AND($G$8="",G13<>""),AND($H$8="",H13<>""),AND($I$8="",I13<>""),AND(#REF!="",#REF!<>""),AND(#REF!="",#REF!<>""),AND(#REF!="",#REF!<>""),AND(#REF!="",#REF!<>""),AND(#REF!="",#REF!<>""),AND(#REF!="",#REF!<>""),AND(#REF!="",#REF!<>""),AND($J$8="",J13<>""),AND($K$8="",K13<>""),AND($L$8="",L13<>""),AND($M$8="",M13<>"")),FALSE,"") -> #REF! | Y13: =IF(AND(B13="",OR(C13<>"",D13<>"",E13<>"",F13<>"",N13<>"",O13<>"",P13<>"",G13<>"",H13<>"",I13<>"",#REF!<>"",#REF!<>"",#REF!<>"",#REF!<>"",#REF!<>"",#REF!<>"",#REF!<>"",J13<>"",K13<>"",L13<>"",M13<>"")),FALSE,"") -> #REF!
S14: =IF(J14="","",J14/SUM(G14:I14)) | T14: =IF(K14="","",K14/SUM(G14:I14)) | U14: =IF(L14="","",L14/SUM(G14:I14)) | V14: =IF(M14="","",M14/(P14+G14+H14+I14+#REF!+#REF!+#REF!+#REF!+#REF!+#REF!+#REF!)) | W14: =IF(SUM(P14+G14+H14+I14+#REF!+#REF!+#REF!+#REF!+#REF!+#REF!+#REF!+J14+K14+L14+M14)=D14,"",FALSE) -> #REF! | X14: =IF(OR(AND(C14="",D14<>""),AND(O14="",P14<>""),AND($G$8="",G14<>""),AND($H$8="",H14<>""),AND($I$8="",I14<>""),AND(#REF!="",#REF!<>""),AND(#REF!="",#REF!<>""),AND(#REF!="",#REF!<>""),AND(#REF!="",#REF!<>""),AND(#REF!="",#REF!<>""),AND(#REF!="",#REF!<>""),AND(#REF!="",#REF!<>""),AND($J$8="",J14<>""),AND($K$8="",K14<>""),AND($L$8="",L14<>""),AND($M$8="",M14<>"")),FALSE,"") -> #REF! | Y14: =IF(AND(B14="",OR(C14<>"",D14<>"",E14<>"",F14<>"",N14<>"",O14<>"",P14<>"",G14<>"",H14<>"",I14<>"",#REF!<>"",#REF!<>"",#REF!<>"",#REF!<>"",#REF!<>"",#REF!<>"",#REF!<>"",J14<>"",K14<>"",L14<>"",M14<>"")),FALSE,"") -> #REF!
S15: =IF(J15="","",J15/SUM(G15:I15)) | T15: =IF(K15="","",K15/SUM(G15:I15)) | U15: =IF(L15="","",L15/SUM(G15:I15)) | V15: =IF(M15="","",M15/(P15+G15+H15+I15+#REF!+#REF!+#REF!+#REF!+#REF!+#REF!+#REF!)) | W15: =IF(SUM(P15+G15+H15+I15+#REF!+#REF!+#REF!+#REF!+#REF!+#REF!+#REF!+J15+K15+L15+M15)=D15,"",FALSE) -> #REF! | X15: =IF(OR(AND(C15="",D15<>""),AND(O15="",P15<>""),AND($G$8="",G15<>""),AND($H$8="",H15<>""),AND($I$8="",I15<>""),AND(#REF!="",#REF!<>""),AND(#REF!="",#REF!<>""),AND(#REF!="",#REF!<>""),AND(#REF!="",#REF!<>""),AND(#REF!="",#REF!<>""),AND(#REF!="",#REF!<>""),AND(#REF!="",#REF!<>""),AND($J$8="",J15<>""),AND($K$8="",K15<>""),AND($L$8="",L15<>""),AND($M$8="",M15<>"")),FALSE,"") -> #REF! | Y15: =IF(AND(B15="",OR(C15<>"",D15<>"",E15<>"",F15<>"",N15<>"",O15<>"",P15<>"",G15<>"",H15<>"",I15<>"",#REF!<>"",#REF!<>"",#REF!<>"",#REF!<>"",#REF!<>"",#REF!<>"",#REF!<>"",J15<>"",K15<>"",L15<>"",M15<>"")),FALSE,"") -> #REF!
S16: =IF(J16="","",J16/SUM(G16:I16)) | T16: =IF(K16="","",K16/SUM(G16:I16)) | U16: =IF(L16="","",L16/SUM(G16:I16)) | V16: =IF(M16="","",M16/(P16+G16+H16+I16+#REF!+#REF!+#REF!+#REF!+#REF!+#REF!+#REF!)) | W16: =IF(SUM(P16+G16+H16+I16+#REF!+#REF!+#REF!+#REF!+#REF!+#REF!+#REF!+J16+K16+L16+M16)=D16,"",FALSE) -> #REF! | X16: =IF(OR(AND(C16="",D16<>""),AND(O16="",P16<>""),AND($G$8="",G16<>""),AND($H$8="",H16<>""),AND($I$8="",I16<>""),AND(#REF!="",#REF!<>""),AND(#REF!="",#REF!<>""),AND(#REF!="",#REF!<>""),AND(#REF!="",#REF!<>""),AND(#REF!="",#REF!<>""),AND(#REF!="",#REF!<>""),AND(#REF!="",#REF!<>""),AND($J$8="",J16<>""),AND($K$8="",K16<>""),AND($L$8="",L16<>""),AND($M$8="",M16<>"")),FALSE,"") -> #REF! | Y16: =IF(AND(B16="",OR(C16<>"",D16<>"",E16<>"",F16<>"",N16<>"",O16<>"",P16<>"",G16<>"",H16<>"",I16<>"",#REF!<>"",#REF!<>"",#REF!<>"",#REF!<>"",#REF!<>"",#REF!<>"",#REF!<>"",J16<>"",K16<>"",L16<>"",M16<>"")),FALSE,"") -> #REF!
S17: =IF(J17="","",J17/SUM(G17:I17)) | T17: =IF(K17="","",K17/SUM(G17:I17)) | U17: =IF(L17="","",L17/SUM(G17:I17)) | V17: =IF(M17="","",M17/(P17+G17+H17+I17+#REF!+#REF!+#REF!+#REF!+#REF!+#REF!+#REF!)) | W17: =IF(SUM(P17+G17+H17+I17+#REF!+#REF!+#REF!+#REF!+#REF!+#REF!+#REF!+J17+K17+L17+M17)=D17,"",FALSE) -> #REF! | X17: =IF(OR(AND(C17="",D17<>""),AND(O17="",P17<>""),AND($G$8="",G17<>""),AND($H$8="",H17<>""),AND($I$8="",I17<>""),AND(#REF!="",#REF!<>""),AND(#REF!="",#REF!<>""),AND(#REF!="",#REF!<>""),AND(#REF!="",#REF!<>""),AND(#REF!="",#REF!<>""),AND(#REF!="",#REF!<>""),AND(#REF!="",#REF!<>""),AND($J$8="",J17<>""),AND($K$8="",K17<>""),AND($L$8="",L17<>""),AND($M$8="",M17<>"")),FALSE,"") -> #REF! | Y17: =IF(AND(B17="",OR(C17<>"",D17<>"",E17<>"",F17<>"",N17<>"",O17<>"",P17<>"",G17<>"",H17<>"",I17<>"",#REF!<>"",#REF!<>"",#REF!<>"",#REF!<>"",#REF!<>"",#REF!<>"",#REF!<>"",J17<>"",K17<>"",L17<>"",M17<>"")),FALSE,"") -> #REF!
S18: =IF(J18="","",J18/SUM(G18:I18)) | T18: =IF(K18="","",K18/SUM(G18:I18)) | U18: =IF(L18="","",L18/SUM(G18:I18)) | V18: =IF(M18="","",M18/(P18+G18+H18+I18+#REF!+#REF!+#REF!+#REF!+#REF!+#REF!+#REF!)) | W18: =IF(SUM(P18+G18+H18+I18+#REF!+#REF!+#REF!+#REF!+#REF!+#REF!+#REF!+J18+K18+L18+M18)=D18,"",FALSE) -> #REF! | X18: =IF(OR(AND(C18="",D18<>""),AND(O18="",P18<>""),AND($G$8="",G18<>""),AND($H$8="",H18<>""),AND($I$8="",I18<>""),AND(#REF!="",#REF!<>""),AND(#REF!="",#REF!<>""),AND(#REF!="",#REF!<>""),AND(#REF!="",#REF!<>""),AND(#REF!="",#REF!<>""),AND(#REF!="",#REF!<>""),AND(#REF!="",#REF!<>""),AND($J$8="",J18<>""),AND($K$8="",K18<>""),AND($L$8="",L18<>""),AND($M$8="",M18<>"")),FALSE,"") -> #REF! | Y18: =IF(AND(B18="",OR(C18<>"",D18<>"",E18<>"",F18<>"",N18<>"",O18<>"",P18<>"",G18<>"",H18<>"",I18<>"",#REF!<>"",#REF!<>"",#REF!<>"",#REF!<>"",#REF!<>"",#REF!<>"",#REF!<>"",J18<>"",K18<>"",L18<>"",M18<>"")),FALSE,"") -> #REF!
S19: =IF(J19="","",J19/SUM(G19:I19)) | T19: =IF(K19="","",K19/SUM(G19:I19)) | U19: =IF(L19="","",L19/SUM(G19:I19)) | V19: =IF(M19="","",M19/(P19+G19+H19+I19+#REF!+#REF!+#REF!+#REF!+#REF!+#REF!+#REF!)) | W19: =IF(SUM(P19+G19+H19+I19+#REF!+#REF!+#REF!+#REF!+#REF!+#REF!+#REF!+J19+K19+L19+M19)=D19,"",FALSE) -> #REF! | X19: =IF(OR(AND(C19="",D19<>""),AND(O19="",P19<>""),AND($G$8="",G19<>""),AND($H$8="",H19<>""),AND($I$8="",I19<>""),AND(#REF!="",#REF!<>""),AND(#REF!="",#REF!<>""),AND(#REF!="",#REF!<>""),AND(#REF!="",#REF!<>""),AND(#REF!="",#REF!<>""),AND(#REF!="",#REF!<>""),AND(#REF!="",#REF!<>""),AND($J$8="",J19<>""),AND($K$8="",K19<>""),AND($L$8="",L19<>""),AND($M$8="",M19<>"")),FALSE,"") -> #REF! | Y19: =IF(AND(B19="",OR(C19<>"",D19<>"",E19<>"",F19<>"",N19<>"",O19<>"",P19<>"",G19<>"",H19<>"",I19<>"",#REF!<>"",#REF!<>"",#REF!<>"",#REF!<>"",#REF!<>"",#REF!<>"",#REF!<>"",J19<>"",K19<>"",L19<>"",M19<>"")),FALSE,"") -> #REF!
S20: =IF(J20="","",J20/SUM(G20:I20)) | T20: =IF(K20="","",K20/SUM(G20:I20)) | U20: =IF(L20="","",L20/SUM(G20:I20)) | V20: =IF(M20="","",M20/(P20+G20+H20+I20+#REF!+#REF!+#REF!+#REF!+#REF!+#REF!+#REF!)) | W20: =IF(SUM(P20+G20+H20+I20+#REF!+#REF!+#REF!+#REF!+#REF!+#REF!+#REF!+J20+K20+L20+M20)=D20,"",FALSE) -> #REF! | X20: =IF(OR(AND(C20="",D20<>""),AND(O20="",P20<>""),AND($G$8="",G20<>""),AND($H$8="",H20<>""),AND($I$8="",I20<>""),AND(#REF!="",#REF!<>""),AND(#REF!="",#REF!<>""),AND(#REF!="",#REF!<>""),AND(#REF!="",#REF!<>""),AND(#REF!="",#REF!<>""),AND(#REF!="",#REF!<>""),AND(#REF!="",#REF!<>""),AND($J$8="",J20<>""),AND($K$8="",K20<>""),AND($L$8="",L20<>""),AND($M$8="",M20<>"")),FALSE,"") -> #REF! | Y20: =IF(AND(B20="",OR(C20<>"",D20<>"",E20<>"",F20<>"",N20<>"",O20<>"",P20<>"",G20<>"",H20<>"",I20<>"",#REF!<>"",#REF!<>"",#REF!<>"",#REF!<>"",#REF!<>"",#REF!<>"",#REF!<>"",J20<>"",K20<>"",L20<>"",M20<>"")),FALSE,"") -> #REF!
S21: =IF(J21="","",J21/SUM(G21:I21)) | T21: =IF(K21="","",K21/SUM(G21:I21)) | U21: =IF(L21="","",L21/SUM(G21:I21)) | V21: =IF(M21="","",M21/(P21+G21+H21+I21+#REF!+#REF!+#REF!+#REF!+#REF!+#REF!+#REF!)) | W21: =IF(SUM(P21+G21+H21+I21+#REF!+#REF!+#REF!+#REF!+#REF!+#REF!+#REF!+J21+K21+L21+M21)=D21,"",FALSE) -> #REF! | X21: =IF(OR(AND(C21="",D21<>""),AND(O21="",P21<>""),AND($G$8="",G21<>""),AND($H$8="",H21<>""),AND($I$8="",I21<>""),AND(#REF!="",#REF!<>""),AND(#REF!="",#REF!<>""),AND(#REF!="",#REF!<>""),AND(#REF!="",#REF!<>""),AND(#REF!="",#REF!<>""),AND(#REF!="",#REF!<>""),AND(#REF!="",#REF!<>""),AND($J$8="",J21<>""),AND($K$8="",K21<>""),AND($L$8="",L21<>""),AND($M$8="",M21<>"")),FALSE,"") -> #REF! | Y21: =IF(AND(B21="",OR(C21<>"",D21<>"",E21<>"",F21<>"",N21<>"",O21<>"",P21<>"",G21<>"",H21<>"",I21<>"",#REF!<>"",#REF!<>"",#REF!<>"",#REF!<>"",#REF!<>"",#REF!<>"",#REF!<>"",J21<>"",K21<>"",L21<>"",M21<>"")),FALSE,"") -> #REF!
S22: =IF(J22="","",J22/SUM(G22:I22)) | T22: =IF(K22="","",K22/SUM(G22:I22)) | U22: =IF(L22="","",L22/SUM(G22:I22)) | V22: =IF(M22="","",M22/(P22+G22+H22+I22+#REF!+#REF!+#REF!+#REF!+#REF!+#REF!+#REF!)) | W22: =IF(SUM(P22+G22+H22+I22+#REF!+#REF!+#REF!+#REF!+#REF!+#REF!+#REF!+J22+K22+L22+M22)=D22,"",FALSE) -> #REF! | X22: =IF(OR(AND(C22="",D22<>""),AND(O22="",P22<>""),AND($G$8="",G22<>""),AND($H$8="",H22<>""),AND($I$8="",I22<>""),AND(#REF!="",#REF!<>""),AND(#REF!="",#REF!<>""),AND(#REF!="",#REF!<>""),AND(#REF!="",#REF!<>""),AND(#REF!="",#REF!<>""),AND(#REF!="",#REF!<>""),AND(#REF!="",#REF!<>""),AND($J$8="",J22<>""),AND($K$8="",K22<>""),AND($L$8="",L22<>""),AND($M$8="",M22<>"")),FALSE,"") -> #REF! | Y22: =IF(AND(B22="",OR(C22<>"",D22<>"",E22<>"",F22<>"",N22<>"",O22<>"",P22<>"",G22<>"",H22<>"",I22<>"",#REF!<>"",#REF!<>"",#REF!<>"",#REF!<>"",#REF!<>"",#REF!<>"",#REF!<>"",J22<>"",K22<>"",L22<>"",M22<>"")),FALSE,"") -> #REF!
... S110: =IF(J110="","",J110/SUM(G110:I110)) | T110: =IF(K110="","",K110/SUM(G110:I110)) | U110: =IF(L110="","",L110/SUM(G110:I110)) | V110: =IF(M110="","",M110/(P110+G110+H110+I110+#REF!+#REF!+#REF!+#REF!+#REF!+#REF!+#REF!)) | W110: =IF(SUM(P110+G110+H110+I110+#REF!+#REF!+#REF!+#REF!+#REF!+#REF!+#REF!+J110+K110+L110+M110)=D110,"",FALSE) -> #REF! | X110: =IF(OR(AND(C110="",D110<>""),AND(O110="",P110<>""),AND($G$8="",G110<>""),AND($H$8="",H110<>""),AND($I$8="",I110<>""),AND(#REF!="",#REF!<>""),AND(#REF!="",#REF!<>""),AND(#REF!="",#REF!<>""),AND(#REF!="",#REF!<>""),AND(#REF!="",#REF!<>""),AND(#REF!="",#REF!<>""),AND(#REF!="",#REF!<>""),AND($J$8="",J110<>""),AND($K$8="",K110<>""),AND($L$8="",L110<>""),AND($M$8="",M110<>"")),FALSE,"") -> #REF! | Y110: =IF(AND(B110="",OR(C110<>"",D110<>"",E110<>"",F110<>"",N110<>"",O110<>"",P110<>"",G110<>"",H110<>"",I110<>"",#REF!<>"",#REF!<>"",#REF!<>"",#REF!<>"",#REF!<>"",#REF!<>"",#REF!<>"",J110<>"",K110<>"",L110<>"",M110<>"")),FALSE,"") -> #REF!
C111: TOTAUX | D111: =SUM(D10:D110) -> 10278 | G111: =IF(SUM(G10:G110)=0,"",SUM(G10:G110)) -> 8565 | H111: =IF(SUM(H10:H110)=0,"",SUM(H10:H110)) | I111: =IF(SUM(I10:I110)=0,"",SUM(I10:I110)) | J111: =IF(SUM(J10:J110)=0,"",SUM(J10:J110)) -> 1713 | K111: =IF(SUM(K10:K110)=0,"",SUM(K10:K110)) | L111: =IF(SUM(L10:L110)=0,"",SUM(L10:L110)) | M111: =IF(SUM(M10:M110)=0,"",SUM(M10:M110)) | P111: =IF(SUM(P10:P110)=0,"",SUM(P10:P110)) | V111: ECART | W111: =SUM(G111:M111)-D111 -> 0

Sheet INTEGRATION
A1: JOURNAL | B1: DATE | C1: COMPTE | D1: NRPIECE | E1: LIB1 | F1: LIB2 | G1: CREDIT | H1: DEBIT | I1: Qte | J1: Code TVA | M1: RADICAL
A2: =IF(AND(G2="",H2=""),"SUPPR",SAISIE!$B$3) -> 0 | B2: =IF(SAISIE!B10="","",IF(LEN(SAISIE!B10)=1,CONCATENATE("0",SAISIE!B10,"/",SAISIE!$B$4,"/",SAISIE!$B$5),CONCATENATE(SAISIE!B10,"/",SAISIE!$B$4,"/",SAISIE!$B$5))) -> 26/08/2024/09/2024 | C2: =IF(SAISIE!B10="","",CONCATENATE($M$2,SAISIE!C10)) -> 0 | D2: =IF(SAISIE!B10="","",SAISIE!E10) -> 0 | E2: =IF(SAISIE!B10="","",SAISIE!F10) -> GADERO : Loyer de septembre facture n° 09-24 réglé le 27/09/2024 par virement | F2: =IF(A2="SUPPR","",IF(SAISIE!N10="","",SAISIE!N10)) | H2: =IF(SAISIE!B10="","",SAISIE!D10) -> 10278 | J2: =IF(AZ10="","","") | M2: =SAISIE!E6 -> 0 | O2: 10
A3: =IF(AND(G3="",H3=""),"SUPPR",SAISIE!$B$3) -> SUPPR | B3: =IF(SAISIE!P10="","",IF(LEN(SAISIE!B10)=1,CONCATENATE("0",SAISIE!B10,"/",SAISIE!$B$4,"/",SAISIE!$B$5),CONCATENATE(SAISIE!B10,"/",SAISIE!$B$4,"/",SAISIE!$B$5))) | C3: =IF(SAISIE!P10="","",SAISIE!O10) | D3: =IF(SAISIE!P10="","",SAISIE!E10) | E3: =IF(SAISIE!P10="","",SAISIE!F10) | F3: =IF(SAISIE!$P10="","",IF(SAISIE!$N10="","",SAISIE!$N10)) | G3: =IF(SAISIE!P10="","",SAISIE!P10) | I3: =IF(SAISIE!$P10="","",SAISIE!$Q10) | J3: =IF(COUNTBLANK(SAISIE!$J$6:$M$6)=4,"",IF(SAISIE!P10="","",IF(SAISIE!J10>0,SAISIE!$J$6,IF(SAISIE!K10>0,SAISIE!$K$6,IF(SAISIE!L10>0,SAISIE!$L$6,IF(SAISIE!M10>0,SAISIE!$M$6,"")))))) | O3: W
A4: =IF(AND(G4="",H4=""),"SUPPR",SAISIE!$B$3) -> 0 | B4: =IF(SAISIE!G10="","",IF(LEN(SAISIE!B10)=1,CONCATENATE("0",SAISIE!B10,"/",SAISIE!$B$4,"/",SAISIE!$B$5),CONCATENATE(SAISIE!B10,"/",SAISIE!$B$4,"/",SAISIE!$B$5))) -> 26/08/2024/09/2024 | C4: =IF(SAISIE!G10="","",SAISIE!$G$8) -> 0 | D4: =IF(SAISIE!G10="","",SAISIE!E10) -> 0 | E4: =IF(SAISIE!G10="","",SAISIE!F10) -> GADERO : Loyer de septembre facture n° 09-24 réglé le 27/09/2024 par virement | F4: =IF(SAISIE!$G10="","",IF(SAISIE!$N10="","",SAISIE!$N10)) | G4: =IF(SAISIE!G10="","",SAISIE!G10) -> 8565 | I4: =IF(SAISIE!$G10="","",SAISIE!$Q10) -> 0 | J4: =IF(COUNTBLANK(SAISIE!$J$6:$M$6)=4,"",IF(SAISIE!G10="","",IF(SAISIE!J10>0,SAISIE!$J$6,IF(SAISIE!K10>0,SAISIE!$K$6,IF(SAISIE!L10>0,SAISIE!$L$6,IF(SAISIE!M10>0,SAISIE!$M$6,"")))))) | O4: G
A5: =IF(AND(G5="",H5=""),"SUPPR",SAISIE!$B$3) -> SUPPR | B5: =IF(SAISIE!H10="","",IF(LEN(SAISIE!B10)=1,CONCATENATE("0",SAISIE!B10,"/",SAISIE!$B$4,"/",SAISIE!$B$5),CONCATENATE(SAISIE!B10,"/",SAISIE!$B$4,"/",SAISIE!$B$5))) | C5: =IF(SAISIE!H10="","",SAISIE!$H$8) | D5: =IF(SAISIE!H10="","",SAISIE!E10) | E5: =IF(SAISIE!H10="","",SAISIE!F10) | F5: =IF(SAISIE!$H10="","",IF(SAISIE!$N10="","",SAISIE!$N10)) | G5: =IF(SAISIE!H10="","",SAISIE!H10) | I5: =IF(SAISIE!$H10="","",SAISIE!$Q10) | J5: =IF(COUNTBLANK(SAISIE!$J$6:$M$6)=4,"",IF(SAISIE!H10="","",IF(SAISIE!J10>0,SAISIE!$J$6,IF(SAISIE!K10>0,SAISIE!$K$6,IF(SAISIE!L10>0,SAISIE!$L$6,IF(SAISIE!M10>0,SAISIE!$M$6,"")))))) | O5: H
A6: =IF(AND(G6="",H6=""),"SUPPR",SAISIE!$B$3) -> SUPPR | B6: =IF(SAISIE!I10="","",IF(LEN(SAISIE!B10)=1,CONCATENATE("0",SAISIE!B10,"/",SAISIE!$B$4,"/",SAISIE!$B$5),CONCATENATE(SAISIE!B10,"/",SAISIE!$B$4,"/",SAISIE!$B$5))) | C6: =IF(SAISIE!I10="","",SAISIE!$I$8) | D6: =IF(SAISIE!I10="","",SAISIE!E10) | E6: =IF(SAISIE!I10="","",SAISIE!F10) | F6: =IF(SAISIE!$I10="","",IF(SAISIE!$N10="","",SAISIE!$N10)) | G6: =IF(SAISIE!I10="","",SAISIE!I10) | I6: =IF(SAISIE!$I10="","",SAISIE!$Q10) | J6: =IF(COUNTBLANK(SAISIE!$J$6:$M$6)=4,"",IF(SAISIE!I10="","",IF(SAISIE!J10>0,SAISIE!$J$6,IF(SAISIE!K10>0,SAISIE!$K$6,IF(SAISIE!L10>0,SAISIE!$L$6,IF(SAISIE!M10>0,SAISIE!$M$6,"")))))) | O6: I
A7: =IF(AND(G7="",H7=""),"SUPPR",SAISIE!$B$3) -> #REF! | B7: =IF(SAISIE!#REF!="","",IF(LEN(SAISIE!B10)=1,CONCATENATE("0",SAISIE!B10,"/",SAISIE!$B$4,"/",SAISIE!$B$5),CONCATENATE(SAISIE!B10,"/",SAISIE!$B$4,"/",SAISIE!$B$5))) -> #REF! | C7: =IF(SAISIE!#REF!="","",SAISIE!#REF!) -> #REF! | D7: =IF(SAISIE!#REF!="","",SAISIE!E10) -> #REF! | E7: =IF(SAISIE!#REF!="","",SAISIE!F10) -> #REF! | F7: =IF(SAISIE!#REF!="","",IF(SAISIE!$N10="","",SAISIE!$N10)) -> #REF! | G7: =IF(SAISIE!#REF!="","",SAISIE!#REF!) -> #REF! | I7: =IF(SAISIE!#REF!="","",SAISIE!$Q10) -> #REF! | J7: =IF(COUNTBLANK(SAISIE!$J$6:$M$6)=4,"",IF(SAISIE!#REF!="","",IF(SAISIE!J10>0,SAISIE!$J$6,IF(SAISIE!K10>0,SAISIE!$K$6,IF(SAISIE!L10>0,SAISIE!$L$6,IF(SAISIE!M10>0,SAISIE!$M$6,"")))))) | O7: J
A8: =IF(AND(G8="",H8=""),"SUPPR",SAISIE!$B$3) -> #REF! | B8: =IF(SAISIE!#REF!="","",IF(LEN(SAISIE!B10)=1,CONCATENATE("0",SAISIE!B10,"/",SAISIE!$B$4,"/",SAISIE!$B$5),CONCATENATE(SAISIE!B10,"/",SAISIE!$B$4,"/",SAISIE!$B$5))) -> #REF! | C8: =IF(SAISIE!#REF!="","",SAISIE!#REF!) -> #REF! | D8: =IF(SAISIE!#REF!="","",SAISIE!E10) -> #REF! | E8: =IF(SAISIE!#REF!="","",SAISIE!F10) -> #REF! | F8: =IF(SAISIE!#REF!="","",IF(SAISIE!$N10="","",SAISIE!$N10)) -> #REF! | G8: =IF(SAISIE!#REF!="","",SAISIE!#REF!) -> #REF! | I8: =IF(SAISIE!#REF!="","",SAISIE!$Q10) -> #REF! | J8: =IF(COUNTBLANK(SAISIE!$J$6:$M$6)=4,"",IF(SAISIE!#REF!="","",IF(SAISIE!J10>0,SAISIE!$J$6,IF(SAISIE!K10>0,SAISIE!$K$6,IF(SAISIE!L10>0,SAISIE!$L$6,IF(SAISIE!M10>0,SAISIE!$M$6,"")))))) | O8: K
A9: =IF(AND(G9="",H9=""),"SUPPR",SAISIE!$B$3) -> #REF! | B9: =IF(SAISIE!#REF!="","",IF(LEN(SAISIE!B10)=1,CONCATENATE("0",SAISIE!B10,"/",SAISIE!$B$4,"/",SAISIE!$B$5),CONCATENATE(SAISIE!B10,"/",SAISIE!$B$4,"/",SAISIE!$B$5))) -> #REF! | C9: =IF(SAISIE!#REF!="","",SAISIE!#REF!) -> #REF! | D9: =IF(SAISIE!#REF!="","",SAISIE!E10) -> #REF! | E9: =IF(SAISIE!#REF!="","",SAISIE!F10) -> #REF! | F9: =IF(SAISIE!#REF!="","",IF(SAISIE!$N10="","",SAISIE!$N10)) -> #REF! | G9: =IF(SAISIE!#REF!="","",SAISIE!#REF!) -> #REF! | I9: =IF(SAISIE!#REF!="","",SAISIE!$Q10) -> #REF! | J9: =IF(COUNTBLANK(SAISIE!$J$6:$M$6)=4,"",IF(SAISIE!#REF!="","",IF(SAISIE!J10>0,SAISIE!$J$6,IF(SAISIE!K10>0,SAISIE!$K$6,IF(SAISIE!L10>0,SAISIE!$L$6,IF(SAISIE!M10>0,SAISIE!$M$6,"")))))) | O9: L
A10: =IF(AND(G10="",H10=""),"SUPPR",SAISIE!$B$3) -> #REF! | B10: =IF(SAISIE!#REF!="","",IF(LEN(SAISIE!B10)=1,CONCATENATE("0",SAISIE!B10,"/",SAISIE!$B$4,"/",SAISIE!$B$5),CONCATENATE(SAISIE!B10,"/",SAISIE!$B$4,"/",SAISIE!$B$5))) -> #REF! | C10: =IF(SAISIE!#REF!="","",SAISIE!#REF!) -> #REF! | D10: =IF(SAISIE!#REF!="","",SAISIE!E10) -> #REF! | E10: =IF(SAISIE!#REF!="","",SAISIE!F10) -> #REF! | F10: =IF(SAISIE!#REF!="","",IF(SAISIE!$N10="","",SAISIE!$N10)) -> #REF! | G10: =IF(SAISIE!#REF!="","",SAISIE!#REF!) -> #REF! | I10: =IF(SAISIE!#REF!="","",SAISIE!$Q10) -> #REF! | J10: =IF(COUNTBLANK(SAISIE!$J$6:$M$6)=4,"",IF(SAISIE!#REF!="","",IF(SAISIE!J10>0,SAISIE!$J$6,IF(SAISIE!K10>0,SAISIE!$K$6,IF(SAISIE!L10>0,SAISIE!$L$6,IF(SAISIE!M10>0,SAISIE!$M$6,"")))))) | O10: M
A11: =IF(AND(G11="",H11=""),"SUPPR",SAISIE!$B$3) -> #REF! | B11: =IF(SAISIE!#REF!="","",IF(LEN(SAISIE!B10)=1,CONCATENATE("0",SAISIE!B10,"/",SAISIE!$B$4,"/",SAISIE!$B$5),CONCATENATE(SAISIE!B10,"/",SAISIE!$B$4,"/",SAISIE!$B$5))) -> #REF! | C11: =IF(SAISIE!#REF!="","",SAISIE!#REF!) -> #REF! | D11: =IF(SAISIE!#REF!="","",SAISIE!E10) -> #REF! | E11: =IF(SAISIE!#REF!="","",SAISIE!F10) -> #REF! | F11: =IF(SAISIE!#REF!="","",IF(SAISIE!$N10="","",SAISIE!$N10)) -> #REF! | G11: =IF(SAISIE!#REF!="","",SAISIE!#REF!) -> #REF! | I11: =IF(SAISIE!#REF!="","",SAISIE!$Q10) -> #REF! | J11: =IF(COUNTBLANK(SAISIE!$J$6:$M$6)=4,"",IF(SAISIE!#REF!="","",IF(SAISIE!J10>0,SAISIE!$J$6,IF(SAISIE!K10>0,SAISIE!$K$6,IF(SAISIE!L10>0,SAISIE!$L$6,IF(SAISIE!M10>0,SAISIE!$M$6,"")))))) | O11: N
A12: =IF(AND(G12="",H12=""),"SUPPR",SAISIE!$B$3) -> #REF! | B12: =IF(SAISIE!#REF!="","",IF(LEN(SAISIE!B10)=1,CONCATENATE("0",SAISIE!B10,"/",SAISIE!$B$4,"/",SAISIE!$B$5),CONCATENATE(SAISIE!B10,"/",SAISIE!$B$4,"/",SAISIE!$B$5))) -> #REF! | C12: =IF(SAISIE!#REF!="","",SAISIE!#REF!) -> #REF! | D12: =IF(SAISIE!#REF!="","",SAISIE!E10) -> #REF! | E12: =IF(SAISIE!#REF!="","",SAISIE!F10) -> #REF! | F12: =IF(SAISIE!#REF!="","",IF(SAISIE!$N10="","",SAISIE!$N10)) -> #REF! | G12: =IF(SAISIE!#REF!="","",SAISIE!#REF!) -> #REF! | I12: =IF(SAISIE!#REF!="","",SAISIE!$Q10) -> #REF! | J12: =IF(COUNTBLANK(SAISIE!$J$6:$M$6)=4,"",IF(SAISIE!#REF!="","",IF(SAISIE!J10>0,SAISIE!$J$6,IF(SAISIE!K10>0,SAISIE!$K$6,IF(SAISIE!L10>0,SAISIE!$L$6,IF(SAISIE!M10>0,SAISIE!$M$6,"")))))) | O12: O
A13: =IF(AND(G13="",H13=""),"SUPPR",SAISIE!$B$3) -> #REF! | B13: =IF(SAISIE!#REF!="","",IF(LEN(SAISIE!B10)=1,CONCATENATE("0",SAISIE!B10,"/",SAISIE!$B$4,"/",SAISIE!$B$5),CONCATENATE(SAISIE!B10,"/",SAISIE!$B$4,"/",SAISIE!$B$5))) -> #REF! | C13: =IF(SAISIE!#REF!="","",SAISIE!#REF!) -> #REF! | D13: =IF(SAISIE!#REF!="","",SAISIE!E10) -> #REF! | E13: =IF(SAISIE!#REF!="","",SAISIE!F10) -> #REF! | F13: =IF(SAISIE!#REF!="","",IF(SAISIE!$N10="","",SAISIE!$N10)) -> #REF! | G13: =IF(SAISIE!#REF!="","",SAISIE!#REF!) -> #REF! | I13: =IF(SAISIE!#REF!="","",SAISIE!$Q10) -> #REF! | J13: =IF(COUNTBLANK(SAISIE!$J$6:$M$6)=4,"",IF(SAISIE!#REF!="","",IF(SAISIE!J10>0,SAISIE!$J$6,IF(SAISIE!K10>0,SAISIE!$K$6,IF(SAISIE!L10>0,SAISIE!$L$6,IF(SAISIE!M10>0,SAISIE!$M$6,"")))))) | O13: P
A14: =IF(AND(G14="",H14=""),"SUPPR",SAISIE!$B$3) -> 0 | B14: =IF(SAISIE!J10="","",IF(LEN(SAISIE!B10)=1,CONCATENATE("0",SAISIE!B10,"/",SAISIE!$B$4,"/",SAISIE!$B$5),CONCATENATE(SAISIE!B10,"/",SAISIE!$B$4,"/",SAISIE!$B$5))) -> 26/08/2024/09/2024 | C14: =IF(SAISIE!J10="","",SAISIE!$J$8) -> 0 | D14: =IF(SAISIE!J10="","",SAISIE!E10) -> 0 | E14: =IF(SAISIE!J10="","",SAISIE!F10) -> GADERO : Loyer de septembre facture n° 09-24 réglé le 27/09/2024 par virement | F14: =IF(SAISIE!$J10="","",IF(SAISIE!$N10="","",SAISIE!$N10)) | G14: =IF(SAISIE!J10="","",SAISIE!J10) -> 1713
A15: =IF(AND(G15="",H15=""),"SUPPR",SAISIE!$B$3) -> SUPPR | B15: =IF(SAISIE!K10="","",IF(LEN(SAISIE!B10)=1,CONCATENATE("0",SAISIE!B10,"/",SAISIE!$B$4,"/",SAISIE!$B$5),CONCATENATE(SAISIE!B10,"/",SAISIE!$B$4,"/",SAISIE!$B$5))) | C15: =IF(SAISIE!K10="","",SAISIE!$K$8) | D15: =IF(SAISIE!K10="","",SAISIE!E10) | E15: =IF(SAISIE!K10="","",SAISIE!F10) | F15: =IF(SAISIE!$K10="","",IF(SAISIE!$N10="","",SAISIE!$N10)) | G15: =IF(SAISIE!K10="","",SAISIE!K10)
A16: =IF(AND(G16="",H16=""),"SUPPR",SAISIE!$B$3) -> SUPPR | B16: =IF(SAISIE!L10="","",IF(LEN(SAISIE!B10)=1,CONCATENATE("0",SAISIE!B10,"/",SAISIE!$B$4,"/",SAISIE!$B$5),CONCATENATE(SAISIE!B10,"/",SAISIE!$B$4,"/",SAISIE!$B$5))) | C16: =IF(SAISIE!L10="","",SAISIE!$L$8) | D16: =IF(SAISIE!L10="","",SAISIE!E10) | E16: =IF(SAISIE!L10="","",SAISIE!F10) | F16: =IF(SAISIE!$L10="","",IF(SAISIE!$N10="","",SAISIE!$N10)) | G16: =IF(SAISIE!L10="","",SAISIE!L10)
A17: =IF(AND(G17="",H17=""),"SUPPR",SAISIE!$B$3) -> SUPPR | B17: =IF(SAISIE!M10="","",IF(LEN(SAISIE!B10)=1,CONCATENATE("0",SAISIE!B10,"/",SAISIE!$B$4,"/",SAISIE!$B$5),CONCATENATE(SAISIE!B10,"/",SAISIE!$B$4,"/",SAISIE!$B$5))) | C17: =IF(SAISIE!M10="","",SAISIE!$M$8) | D17: =IF(SAISIE!M10="","",SAISIE!E10) | E17: =IF(SAISIE!M10="","",SAISIE!F10) | F17: =IF(SAISIE!$M10="","",IF(SAISIE!$N10="","",SAISIE!$N10)) | G17: =IF(SAISIE!M10="","",SAISIE!M10)
A18: =IF(AND(G18="",H18=""),"SUPPR",SAISIE!$B$3) -> SUPPR | B18: =IF(SAISIE!B11="","",IF(LEN(SAISIE!B11)=1,CONCATENATE("0",SAISIE!B11,"/",SAISIE!$B$4,"/",SAISIE!$B$5),CONCATENATE(SAISIE!B11,"/",SAISIE!$B$4,"/",SAISIE!$B$5))) | C18: =IF(SAISIE!B11="","",CONCATENATE($M$2,SAISIE!C11)) | D18: =IF(SAISIE!B11="","",SAISIE!E11) | E18: =IF(SAISIE!B11="","",SAISIE!F11) | F18: =IF(A18="SUPPR","",IF(SAISIE!N11="","",SAISIE!N11)) | H18: =IF(SAISIE!B11="","",SAISIE!D11) | J18: =IF(AZ11="","","") | O18: =O2+1 -> 11
A19: =IF(AND(G19="",H19=""),"SUPPR",SAISIE!$B$3) -> SUPPR | B19: =IF(SAISIE!P11="","",IF(LEN(SAISIE!B11)=1,CONCATENATE("0",SAISIE!B11,"/",SAISIE!$B$4,"/",SAISIE!$B$5),CONCATENATE(SAISIE!B11,"/",SAISIE!$B$4,"/",SAISIE!$B$5))) | C19: =IF(SAISIE!P11="","",SAISIE!O11) | D19: =IF(SAISIE!P11="","",SAISIE!E11) | E19: =IF(SAISIE!P11="","",SAISIE!F11) | F19: =IF(SAISIE!$P11="","",IF(SAISIE!$N11="","",SAISIE!$N11)) | G19: =IF(SAISIE!P11="","",SAISIE!P11) | I19: =IF(SAISIE!$P11="","",SAISIE!$Q11) | J19: =IF(COUNTBLANK(SAISIE!$J$6:$M$6)=4,"",IF(SAISIE!P11="","",IF(SAISIE!J11>0,SAISIE!$J$6,IF(SAISIE!K11>0,SAISIE!$K$6,IF(SAISIE!L11>0,SAISIE!$L$6,IF(SAISIE!M11>0,SAISIE!$M$6,"")))))) | O19: W
A20: =IF(AND(G20="",H20=""),"SUPPR",SAISIE!$B$3) -> SUPPR | B20: =IF(SAISIE!G11="","",IF(LEN(SAISIE!B11)=1,CONCATENATE("0",SAISIE!B11,"/",SAISIE!$B$4,"/",SAISIE!$B$5),CONCATENATE(SAISIE!B11,"/",SAISIE!$B$4,"/",SAISIE!$B$5))) | C20: =IF(SAISIE!G11="","",SAISIE!$G$8) | D20: =IF(SAISIE!G11="","",SAISIE!E11) | E20: =IF(SAISIE!G11="","",SAISIE!F11) | F20: =IF(SAISIE!$G11="","",IF(SAISIE!$N11="","",SAISIE!$N11)) | G20: =IF(SAISIE!G11="","",SAISIE!G11) | I20: =IF(SAISIE!$G11="","",SAISIE!$Q11) | J20: =IF(COUNTBLANK(SAISIE!$J$6:$M$6)=4,"",IF(SAISIE!G11="","",IF(SAISIE!J11>0,SAISIE!$J$6,IF(SAISIE!K11>0,SAISIE!$K$6,IF(SAISIE!L11>0,SAISIE!$L$6,IF(SAISIE!M11>0,SAISIE!$M$6,"")))))) | O20: G
A21: =IF(AND(G21="",H21=""),"SUPPR",SAISIE!$B$3) -> SUPPR | B21: =IF(SAISIE!H11="","",IF(LEN(SAISIE!B11)=1,CONCATENATE("0",SAISIE!B11,"/",SAISIE!$B$4,"/",SAISIE!$B$5),CONCATENATE(SAISIE!B11,"/",SAISIE!$B$4,"/",SAISIE!$B$5))) | C21: =IF(SAISIE!H11="","",SAISIE!$H$8) | D21: =IF(SAISIE!H11="","",SAISIE!E11) | E21: =IF(SAISIE!H11="","",SAISIE!F11) | F21: =IF(SAISIE!$H11="","",IF(SAISIE!$N11="","",SAISIE!$N11)) | G21: =IF(SAISIE!H11="","",SAISIE!H11) | I21: =IF(SAISIE!$H11="","",SAISIE!$Q11) | J21: =IF(COUNTBLANK(SAISIE!$J$6:$M$6)=4,"",IF(SAISIE!H11="","",IF(SAISIE!J11>0,SAISIE!$J$6,IF(SAISIE!K11>0,SAISIE!$K$6,IF(SAISIE!L11>0,SAISIE!$L$6,IF(SAISIE!M11>0,SAISIE!$M$6,"")))))) | O21: H
A22: =IF(AND(G22="",H22=""),"SUPPR",SAISIE!$B$3) -> SUPPR | B22: =IF(SAISIE!I11="","",IF(LEN(SAISIE!B11)=1,CONCATENATE("0",SAISIE!B11,"/",SAISIE!$B$4,"/",SAISIE!$B$5),CONCATENATE(SAISIE!B11,"/",SAISIE!$B$4,"/",SAISIE!$B$5))) | C22: =IF(SAISIE!I11="","",SAISIE!$I$8) | D22: =IF(SAISIE!I11="","",SAISIE!E11) | E22: =IF(SAISIE!I11="","",SAISIE!F11) | F22: =IF(SAISIE!$I11="","",IF(SAISIE!$N11="","",SAISIE!$N11)) | G22: =IF(SAISIE!I11="","",SAISIE!I11) | I22: =IF(SAISIE!$I11="","",SAISIE!$Q11) | J22: =IF(COUNTBLANK(SAISIE!$J$6:$M$6)=4,"",IF(SAISIE!I11="","",IF(SAISIE!J11>0,SAISIE!$J$6,IF(SAISIE!K11>0,SAISIE!$K$6,IF(SAISIE!L11>0,SAISIE!$L$6,IF(SAISIE!M11>0,SAISIE!$M$6,"")))))) | O22: I
A23: =IF(AND(G23="",H23=""),"SUPPR",SAISIE!$B$3) -> #REF! | B23: =IF(SAISIE!#REF!="","",IF(LEN(SAISIE!B11)=1,CONCATENATE("0",SAISIE!B11,"/",SAISIE!$B$4,"/",SAISIE!$B$5),CONCATENATE(SAISIE!B11,"/",SAISIE!$B$4,"/",SAISIE!$B$5))) -> #REF! | C23: =IF(SAISIE!#REF!="","",SAISIE!#REF!) -> #REF! | D23: =IF(SAISIE!#REF!="","",SAISIE!E11) -> #REF! | E23: =IF(SAISIE!#REF!="","",SAISIE!F11) -> #REF! | F23: =IF(SAISIE!#REF!="","",IF(SAISIE!$N11="","",SAISIE!$N11)) -> #REF! | G23: =IF(SAISIE!#REF!="","",SAISIE!#REF!) -> #REF! | I23: =IF(SAISIE!#REF!="","",SAISIE!$Q11) -> #REF! | J23: =IF(COUNTBLANK(SAISIE!$J$6:$M$6)=4,"",IF(SAISIE!#REF!="","",IF(SAISIE!J11>0,SAISIE!$J$6,IF(SAISIE!K11>0,SAISIE!$K$6,IF(SAISIE!L11>0,SAISIE!$L$6,IF(SAISIE!M11>0,SAISIE!$M$6,"")))))) | O23: J
A24: =IF(AND(G24="",H24=""),"SUPPR",SAISIE!$B$3) -> #REF! | B24: =IF(SAISIE!#REF!="","",IF(LEN(SAISIE!B11)=1,CONCATENATE("0",SAISIE!B11,"/",SAISIE!$B$4,"/",SAISIE!$B$5),CONCATENATE(SAISIE!B11,"/",SAISIE!$B$4,"/",SAISIE!$B$5))) -> #REF! | C24: =IF(SAISIE!#REF!="","",SAISIE!#REF!) -> #REF! | D24: =IF(SAISIE!#REF!="","",SAISIE!E11) -> #REF! | E24: =IF(SAISIE!#REF!="","",SAISIE!F11) -> #REF! | F24: =IF(SAISIE!#REF!="","",IF(SAISIE!$N11="","",SAISIE!$N11)) -> #REF! | G24: =IF(SAISIE!#REF!="","",SAISIE!#REF!) -> #REF! | I24: =IF(SAISIE!#REF!="","",SAISIE!$Q11) -> #REF! | J24: =IF(COUNTBLANK(SAISIE!$J$6:$M$6)=4,"",IF(SAISIE!#REF!="","",IF(SAISIE!J11>0,SAISIE!$J$6,IF(SAISIE!K11>0,SAISIE!$K$6,IF(SAISIE!L11>0,SAISIE!$L$6,IF(SAISIE!M11>0,SAISIE!$M$6,"")))))) | O24: K
A25: =IF(AND(G25="",H25=""),"SUPPR",SAISIE!$B$3) -> #REF! | B25: =IF(SAISIE!#REF!="","",IF(LEN(SAISIE!B11)=1,CONCATENATE("0",SAISIE!B11,"/",SAISIE!$B$4,"/",SAISIE!$B$5),CONCATENATE(SAISIE!B11,"/",SAISIE!$B$4,"/",SAISIE!$B$5))) -> #REF! | C25: =IF(SAISIE!#REF!="","",SAISIE!#REF!) -> #REF! | D25: =IF(SAISIE!#REF!="","",SAISIE!E11) -> #REF! | E25: =IF(SAISIE!#REF!="","",SAISIE!F11) -> #REF! | F25: =IF(SAISIE!#REF!="","",IF(SAISIE!$N11="","",SAISIE!$N11)) -> #REF! | G25: =IF(SAISIE!#REF!="","",SAISIE!#REF!) -> #REF! | I25: =IF(SAISIE!#REF!="","",SAISIE!$Q11) -> #REF! | J25: =IF(COUNTBLANK(SAISIE!$J$6:$M$6)=4,"",IF(SAISIE!#REF!="","",IF(SAISIE!J11>0,SAISIE!$J$6,IF(SAISIE!K11>0,SAISIE!$K$6,IF(SAISIE!L11>0,SAISIE!$L$6,IF(SAISIE!M11>0,SAISIE!$M$6,"")))))) | O25: L
A26: =IF(AND(G26="",H26=""),"SUPPR",SAISIE!$B$3) -> #REF! | B26: =IF(SAISIE!#REF!="","",IF(LEN(SAISIE!B11)=1,CONCATENATE("0",SAISIE!B11,"/",SAISIE!$B$4,"/",SAISIE!$B$5),CONCATENATE(SAISIE!B11,"/",SAISIE!$B$4,"/",SAISIE!$B$5))) -> #REF! | C26: =IF(SAISIE!#REF!="","",SAISIE!#REF!) -> #REF! | D26: =IF(SAISIE!#REF!="","",SAISIE!E11) -> #REF! | E26: =IF(SAISIE!#REF!="","",SAISIE!F11) -> #REF! | F26: =IF(SAISIE!#REF!="","",IF(SAISIE!$N11="","",SAISIE!$N11)) -> #REF! | G26: =IF(SAISIE!#REF!="","",SAISIE!#REF!) -> #REF! | I26: =IF(SAISIE!#REF!="","",SAISIE!$Q11) -> #REF! | J26: =IF(COUNTBLANK(SAISIE!$J$6:$M$6)=4,"",IF(SAISIE!#REF!="","",IF(SAISIE!J11>0,SAISIE!$J$6,IF(SAISIE!K11>0,SAISIE!$K$6,IF(SAISIE!L11>0,SAISIE!$L$6,IF(SAISIE!M11>0,SAISIE!$M$6,"")))))) | O26: M
A27: =IF(AND(G27="",H27=""),"SUPPR",SAISIE!$B$3) -> #REF! | B27: =IF(SAISIE!#REF!="","",IF(LEN(SAISIE!B11)=1,CONCATENATE("0",SAISIE!B11,"/",SAISIE!$B$4,"/",SAISIE!$B$5),CONCATENATE(SAISIE!B11,"/",SAISIE!$B$4,"/",SAISIE!$B$5))) -> #REF! | C27: =IF(SAISIE!#REF!="","",SAISIE!#REF!) -> #REF! | D27: =IF(SAISIE!#REF!="","",SAISIE!E11) -> #REF! | E27: =IF(SAISIE!#REF!="","",SAISIE!F11) -> #REF! | F27: =IF(SAISIE!#REF!="","",IF(SAISIE!$N11="","",SAISIE!$N11)) -> #REF! | G27: =IF(SAISIE!#REF!="","",SAISIE!#REF!) -> #REF! | I27: =IF(SAISIE!#REF!="","",SAISIE!$Q11) -> #REF! | J27: =IF(COUNTBLANK(SAISIE!$J$6:$M$6)=4,"",IF(SAISIE!#REF!="","",IF(SAISIE!J11>0,SAISIE!$J$6,IF(SAISIE!K11>0,SAISIE!$K$6,IF(SAISIE!L11>0,SAISIE!$L$6,IF(SAISIE!M11>0,SAISIE!$M$6,"")))))) | O27: N
A28: =IF(AND(G28="",H28=""),"SUPPR",SAISIE!$B$3) -> #REF! | B28: =IF(SAISIE!#REF!="","",IF(LEN(SAISIE!B11)=1,CONCATENATE("0",SAISIE!B11,"/",SAISIE!$B$4,"/",SAISIE!$B$5),CONCATENATE(SAISIE!B11,"/",SAISIE!$B$4,"/",SAISIE!$B$5))) -> #REF! | C28: =IF(SAISIE!#REF!="","",SAISIE!#REF!) -> #REF! | D28: =IF(SAISIE!#REF!="","",SAISIE!E11) -> #REF! | E28: =IF(SAISIE!#REF!="","",SAISIE!F11) -> #REF! | F28: =IF(SAISIE!#REF!="","",IF(SAISIE!$N11="","",SAISIE!$N11)) -> #REF! | G28: =IF(SAISIE!#REF!="","",SAISIE!#REF!) -> #REF! | I28: =IF(SAISIE!#REF!="","",SAISIE!$Q11) -> #REF! | J28: =IF(COUNTBLANK(SAISIE!$J$6:$M$6)=4,"",IF(SAISIE!#REF!="","",IF(SAISIE!J11>0,SAISIE!$J$6,IF(SAISIE!K11>0,SAISIE!$K$6,IF(SAISIE!L11>0,SAISIE!$L$6,IF(SAISIE!M11>0,SAISIE!$M$6,"")))))) | O28: O
A29: =IF(AND(G29="",H29=""),"SUPPR",SAISIE!$B$3) -> #REF! | B29: =IF(SAISIE!#REF!="","",IF(LEN(SAISIE!B11)=1,CONCATENATE("0",SAISIE!B11,"/",SAISIE!$B$4,"/",SAISIE!$B$5),CONCATENATE(SAISIE!B11,"/",SAISIE!$B$4,"/",SAISIE!$B$5))) -> #REF! | C29: =IF(SAISIE!#REF!="","",SAISIE!#REF!) -> #REF! | D29: =IF(SAISIE!#REF!="","",SAISIE!E11) -> #REF! | E29: =IF(SAISIE!#REF!="","",SAISIE!F11) -> #REF! | F29: =IF(SAISIE!#REF!="","",IF(SAISIE!$N11="","",SAISIE!$N11)) -> #REF! | G29: =IF(SAISIE!#REF!="","",SAISIE!#REF!) -> #REF! | I29: =IF(SAISIE!#REF!="","",SAISIE!$Q11) -> #REF! | J29: =IF(COUNTBLANK(SAISIE!$J$6:$M$6)=4,"",IF(SAISIE!#REF!="","",IF(SAISIE!J11>0,SAISIE!$J$6,IF(SAISIE!K11>0,SAISIE!$K$6,IF(SAISIE!L11>0,SAISIE!$L$6,IF(SAISIE!M11>0,SAISIE!$M$6,"")))))) | O29: P
A30: =IF(AND(G30="",H30=""),"SUPPR",SAISIE!$B$3) -> SUPPR | B30: =IF(SAISIE!J11="","",IF(LEN(SAISIE!B11)=1,CONCATENATE("0",SAISIE!B11,"/",SAISIE!$B$4,"/",SAISIE!$B$5),CONCATENATE(SAISIE!B11,"/",SAISIE!$B$4,"/",SAISIE!$B$5))) | C30: =IF(SAISIE!J11="","",SAISIE!$J$8) | D30: =IF(SAISIE!J11="","",SAISIE!E11) | E30: =IF(SAISIE!J11="","",SAISIE!F11) | F30: =IF(SAISIE!$J11="","",IF(SAISIE!$N11="","",SAISIE!$N11)) | G30: =IF(SAISIE!J11="","",SAISIE!J11)
A31: =IF(AND(G31="",H31=""),"SUPPR",SAISIE!$B$3) -> SUPPR | B31: =IF(SAISIE!K11="","",IF(LEN(SAISIE!B11)=1,CONCATENATE("0",SAISIE!B11,"/",SAISIE!$B$4,"/",SAISIE!$B$5),CONCATENATE(SAISIE!B11,"/",SAISIE!$B$4,"/",SAISIE!$B$5))) | C31: =IF(SAISIE!K11="","",SAISIE!$K$8) | D31: =IF(SAISIE!K11="","",SAISIE!E11) | E31: =IF(SAISIE!K11="","",SAISIE!F11) | F31: =IF(SAISIE!$K11="","",IF(SAISIE!$N11="","",SAISIE!$N11)) | G31: =IF(SAISIE!K11="","",SAISIE!K11)
A32: =IF(AND(G32="",H32=""),"SUPPR",SAISIE!$B$3) -> SUPPR | B32: =IF(SAISIE!L11="","",IF(LEN(SAISIE!B11)=1,CONCATENATE("0",SAISIE!B11,"/",SAISIE!$B$4,"/",SAISIE!$B$5),CONCATENATE(SAISIE!B11,"/",SAISIE!$B$4,"/",SAISIE!$B$5))) | C32: =IF(SAISIE!L11="","",SAISIE!$L$8) | D32: =IF(SAISIE!L11="","",SAISIE!E11) | E32: =IF(SAISIE!L11="","",SAISIE!F11) | F32: =IF(SAISIE!$L11="","",IF(SAISIE!$N11="","",SAISIE!$N11)) | G32: =IF(SAISIE!L11="","",SAISIE!L11)
A33: =IF(AND(G33="",H33=""),"SUPPR",SAISIE!$B$3) -> SUPPR | B33: =IF(SAISIE!M11="","",IF(LEN(SAISIE!B11)=1,CONCATENATE("0",SAISIE!B11,"/",SAISIE!$B$4,"/",SAISIE!$B$5),CONCATENATE(SAISIE!B11,"/",SAISIE!$B$4,"/",SAISIE!$B$5))) | C33: =IF(SAISIE!M11="","",SAISIE!$M$8) | D33: =IF(SAISIE!M11="","",SAISIE!E11) | E33: =IF(SAISIE!M11="","",SAISIE!F11) | F33: =IF(SAISIE!$M11="","",IF(SAISIE!$N11="","",SAISIE!$N11)) | G33: =IF(SAISIE!M11="","",SAISIE!M11)
A34: =IF(AND(G34="",H34=""),"SUPPR",SAISIE!$B$3) -> SUPPR | B34: =IF(SAISIE!B12="","",IF(LEN(SAISIE!B12)=1,CONCATENATE("0",SAISIE!B12,"/",SAISIE!$B$4,"/",SAISIE!$B$5),CONCATENATE(SAISIE!B12,"/",SAISIE!$B$4,"/",SAISIE!$B$5))) | C34: =IF(SAISIE!B12="","",CONCATENATE($M$2,SAISIE!C12)) | D34: =IF(SAISIE!B12="","",SAISIE!E12) | E34: =IF(SAISIE!B12="","",SAISIE!F12) | F34: =IF(A34="SUPPR","",IF(SAISIE!$N12="","",SAISIE!$N12)) | H34: =IF(SAISIE!B12="","",SAISIE!D12) | J34: =IF(AZ12="","","") | O34: =O18+1 -> 12
A35: =IF(AND(G35="",H35=""),"SUPPR",SAISIE!$B$3) -> SUPPR | B35: =IF(SAISIE!P12="","",IF(LEN(SAISIE!B12)=1,CONCATENATE("0",SAISIE!B12,"/",SAISIE!$B$4,"/",SAISIE!$B$5),CONCATENATE(SAISIE!B12,"/",SAISIE!$B$4,"/",SAISIE!$B$5))) | C35: =IF(SAISIE!P12="","",SAISIE!O12) | D35: =IF(SAISIE!P12="","",SAISIE!E12) | E35: =IF(SAISIE!P12="","",SAISIE!F12) | F35: =IF(SAISIE!$P12="","",IF(SAISIE!$N12="","",SAISIE!$N12)) | G35: =IF(SAISIE!P12="","",SAISIE!P12) | I35: =IF(SAISIE!$P12="","",SAISIE!$Q12) | J35: =IF(COUNTBLANK(SAISIE!$J$6:$M$6)=4,"",IF(SAISIE!P12="","",IF(SAISIE!J12>0,SAISIE!$J$6,IF(SAISIE!K12>0,SAISIE!$K$6,IF(SAISIE!L12>0,SAISIE!$L$6,IF(SAISIE!M12>0,SAISIE!$M$6,"")))))) | O35: W
A36: =IF(AND(G36="",H36=""),"SUPPR",SAISIE!$B$3) -> SUPPR | B36: =IF(SAISIE!G12="","",IF(LEN(SAISIE!B12)=1,CONCATENATE("0",SAISIE!B12,"/",SAISIE!$B$4,"/",SAISIE!$B$5),CONCATENATE(SAISIE!B12,"/",SAISIE!$B$4,"/",SAISIE!$B$5))) | C36: =IF(SAISIE!G12="","",SAISIE!$G$8) | D36: =IF(SAISIE!G12="","",SAISIE!E12) | E36: =IF(SAISIE!G12="","",SAISIE!F12) | F36: =IF(SAISIE!$G12="","",IF(SAISIE!$N12="","",SAISIE!$N12)) | G36: =IF(SAISIE!G12="","",SAISIE!G12) | I36: =IF(SAISIE!$G12="","",SAISIE!$Q12) | J36: =IF(COUNTBLANK(SAISIE!$J$6:$M$6)=4,"",IF(SAISIE!G12="","",IF(SAISIE!J12>0,SAISIE!$J$6,IF(SAISIE!K12>0,SAISIE!$K$6,IF(SAISIE!L12>0,SAISIE!$L$6,IF(SAISIE!M12>0,SAISIE!$M$6,"")))))) | O36: G
A37: =IF(AND(G37="",H37=""),"SUPPR",SAISIE!$B$3) -> SUPPR | B37: =IF(SAISIE!H12="","",IF(LEN(SAISIE!B12)=1,CONCATENATE("0",SAISIE!B12,"/",SAISIE!$B$4,"/",SAISIE!$B$5),CONCATENATE(SAISIE!B12,"/",SAISIE!$B$4,"/",SAISIE!$B$5))) | C37: =IF(SAISIE!H12="","",SAISIE!$H$8) | D37: =IF(SAISIE!H12="","",SAISIE!E12) | E37: =IF(SAISIE!H12="","",SAISIE!F12) | F37: =IF(SAISIE!$H12="","",IF(SAISIE!$N12="","",SAISIE!$N12)) | G37: =IF(SAISIE!H12="","",SAISIE!H12) | I37: =IF(SAISIE!$H12="","",SAISIE!$Q12) | J37: =IF(COUNTBLANK(SAISIE!$J$6:$M$6)=4,"",IF(SAISIE!H12="","",IF(SAISIE!J12>0,SAISIE!$J$6,IF(SAISIE!K12>0,SAISIE!$K$6,IF(SAISIE!L12>0,SAISIE!$L$6,IF(SAISIE!M12>0,SAISIE!$M$6,"")))))) | O37: H
A38: =IF(AND(G38="",H38=""),"SUPPR",SAISIE!$B$3) -> SUPPR | B38: =IF(SAISIE!I12="","",IF(LEN(SAISIE!B12)=1,CONCATENATE("0",SAISIE!B12,"/",SAISIE!$B$4,"/",SAISIE!$B$5),CONCATENATE(SAISIE!B12,"/",SAISIE!$B$4,"/",SAISIE!$B$5))) | C38: =IF(SAISIE!I12="","",SAISIE!$I$8) | D38: =IF(SAISIE!I12="","",SAISIE!E12) | E38: =IF(SAISIE!I12="","",SAISIE!F12) | F38: =IF(SAISIE!$I12="","",IF(SAISIE!$N12="","",SAISIE!$N12)) | G38: =IF(SAISIE!I12="","",SAISIE!I12) | I38: =IF(SAISIE!$I12="","",SAISIE!$Q12) | J38: =IF(COUNTBLANK(SAISIE!$J$6:$M$6)=4,"",IF(SAISIE!I12="","",IF(SAISIE!J12>0,SAISIE!$J$6,IF(SAISIE!K12>0,SAISIE!$K$6,IF(SAISIE!L12>0,SAISIE!$L$6,IF(SAISIE!M12>0,SAISIE!$M$6,"")))))) | O38: I
A39: =IF(AND(G39="",H39=""),"SUPPR",SAISIE!$B$3) -> #REF! | B39: =IF(SAISIE!#REF!="","",IF(LEN(SAISIE!B12)=1,CONCATENATE("0",SAISIE!B12,"/",SAISIE!$B$4,"/",SAISIE!$B$5),CONCATENATE(SAISIE!B12,"/",SAISIE!$B$4,"/",SAISIE!$B$5))) -> #REF! | C39: =IF(SAISIE!#REF!="","",SAISIE!#REF!) -> #REF! | D39: =IF(SAISIE!#REF!="","",SAISIE!E12) -> #REF! | E39: =IF(SAISIE!#REF!="","",SAISIE!F12) -> #REF! | F39: =IF(SAISIE!#REF!="","",IF(SAISIE!$N12="","",SAISIE!$N12)) -> #REF! | G39: =IF(SAISIE!#REF!="","",SAISIE!#REF!) -> #REF! | I39: =IF(SAISIE!#REF!="","",SAISIE!$Q12) -> #REF! | J39: =IF(COUNTBLANK(SAISIE!$J$6:$M$6)=4,"",IF(SAISIE!#REF!="","",IF(SAISIE!J12>0,SAISIE!$J$6,IF(SAISIE!K12>0,SAISIE!$K$6,IF(SAISIE!L12>0,SAISIE!$L$6,IF(SAISIE!M12>0,SAISIE!$M$6,"")))))) | O39: J
A40: =IF(AND(G40="",H40=""),"SUPPR",SAISIE!$B$3) -> #REF! | B40: =IF(SAISIE!#REF!="","",IF(LEN(SAISIE!B12)=1,CONCATENATE("0",SAISIE!B12,"/",SAISIE!$B$4,"/",SAISIE!$B$5),CONCATENATE(SAISIE!B12,"/",SAISIE!$B$4,"/",SAISIE!$B$5))) -> #REF! | C40: =IF(SAISIE!#REF!="","",SAISIE!#REF!) -> #REF! | D40: =IF(SAISIE!#REF!="","",SAISIE!E12) -> #REF! | E40: =IF(SAISIE!#REF!="","",SAISIE!F12) -> #REF! | F40: =IF(SAISIE!#REF!="","",IF(SAISIE!$N12="","",SAISIE!$N12)) -> #REF! | G40: =IF(SAISIE!#REF!="","",SAISIE!#REF!) -> #REF! | I40: =IF(SAISIE!#REF!="","",SAISIE!$Q12) -> #REF! | J40: =IF(COUNTBLANK(SAISIE!$J$6:$M$6)=4,"",IF(SAISIE!#REF!="","",IF(SAISIE!J12>0,SAISIE!$J$6,IF(SAISIE!K12>0,SAISIE!$K$6,IF(SAISIE!L12>0,SAISIE!$L$6,IF(SAISIE!M12>0,SAISIE!$M$6,"")))))) | O40: K
...
